Found cached dataset xnli (/home/lcur1101/.cache/huggingface/datasets/xnli/fr/1.1.0/818164464f9c9fd15776ca8a00423b074344c3e929d00a2c1a84aa5a50c928bd)
task  NLI
self.device  cuda
  0%|          | 0/3 [00:00<?, ?it/s]100%|██████████| 3/3 [00:00<00:00, 387.54it/s]
/home/lcur1101/.conda/envs/dl2022/lib/python3.10/site-packages/torch/utils/data/dataloader.py:561: UserWarning: This DataLoader will create 4 worker processes in total. Our suggested max number of worker in current system is 3, which is smaller than what this DataLoader is going to create. Please be aware that excessive worker creation might get DataLoader running slow or even freeze, lower the worker number to avoid potential slowness/freeze if necessary.
  warnings.warn(_create_warning_msg(
Token indices sequence length is longer than the specified maximum sequence length for this model (1196 > 512). Running this sequence through the model will result in indexing errors
Batch number: 0 , batch size : 2
Time taken to execute prompt gen: 0:00:00.000111
couldn't find 2 in the mapping
couldn't find 2 in the mapping
couldn't find 0 in the mapping
couldn't find 2 in the mapping
couldn't find 2 in the mapping
couldn't find 0 in the mapping
couldn't find 1 in the mapping
couldn't find 1 in the mapping
couldn't find 0 in the mapping
couldn't find 1 in the mapping
couldn't find 2 in the mapping
couldn't find 2 in the mapping
couldn't find 2 in the mapping
couldn't find 0 in the mapping
couldn't find 0 in the mapping
couldn't find 0 in the mapping
couldn't find 1 in the mapping
couldn't find 2 in the mapping
couldn't find 1 in the mapping
couldn't find 1 in the mapping
couldn't find 2 in the mapping
couldn't find 0 in the mapping
couldn't find 2 in the mapping
couldn't find 1 in the mapping
couldn't find 0 in the mapping
couldn't find 1 in the mapping
couldn't find 0 in the mapping
couldn't find 1 in the mapping
couldn't find 1 in the mapping
couldn't find 0 in the mapping
couldn't find 1 in the mapping
couldn't find 0 in the mapping
Time taken to execute mapping: 0:00:00.000275
Traceback (most recent call last):
  File "/home/lcur1101/ATCS_group3/code/pipeline_file.py", line 193, in <module>
    acc = pipeline(LM_model, task, prompt_generator)
  File "/home/lcur1101/ATCS_group3/code/pipeline_file.py", line 152, in pipeline
    answers_probs, pred_answer = model(prompt, possible_answers)
  File "/home/lcur1101/ATCS_group3/code/main_model.py", line 36, in __call__
    possible_answers_ids = [vocab[answer] for answer in possible_answers]
  File "/home/lcur1101/ATCS_group3/code/main_model.py", line 36, in <listcomp>
    possible_answers_ids = [vocab[answer] for answer in possible_answers]
KeyError: 'entailment'
srun: error: r35n2: task 0: Exited with exit code 1
