Found cached dataset xnli (/home/lcur1101/.cache/huggingface/datasets/xnli/de/1.1.0/818164464f9c9fd15776ca8a00423b074344c3e929d00a2c1a84aa5a50c928bd)
****Start Time: 2023-05-21_16-47-52
Loading model bigscience/bloom-560m
Model bigscience/bloom-560m loaded
Available device is cuda
Model device: cuda:0
----------- 42 de bigscience/bloom-560m NLI active 0 50 16 --------------
Loading NLI dataset for de
  0%|          | 0/3 [00:00<?, ?it/s]100%|██████████| 3/3 [00:00<00:00, 240.96it/s]
NLI dataset loaded
len of entail_examples , neutral_examples, contra_examples:  16 16 16
len dataset  48
Batch: 0 , batch size: 16, sample_size: 50
answer  {'input_ids': [1650], 'attention_mask': [1]}
answer  {'input_ids': [951, 265], 'attention_mask': [1, 1]}
probs_ shape torch.Size([16])
Traceback (most recent call last):
  File "/home/lcur1101/ATCS_group3/src/main.py", line 169, in <module>
    pipeline(seeds, languages, models, tasks, prompt_types,
  File "/home/lcur1101/ATCS_group3/src/main.py", line 125, in pipeline
    logits_dict_for_prompt = get_prompt_acc(
  File "/home/lcur1101/ATCS_group3/src/main.py", line 56, in get_prompt_acc
    answers_probs_batch, pred_answer_batch = LM(
  File "/home/lcur1101/ATCS_group3/src/models/model.py", line 174, in __call__
    answers_probs[:, idx] = probs_.transpose(0, 1)
IndexError: Dimension out of range (expected to be in range of [-1, 0], but got 1)
srun: error: r29n3: task 0: Exited with exit code 1
